Workbook

Sheet Summary
A1: UAT Checklist — Data Exchange
A2: No. | B2: User Role | C2: Not Executed | D2: In Progress | E2: Passed | F2: Skipped | G2: Failed | H2: Blocked | I2: Total | J2: Remark
A3: 1 | B3: ผู้ใช้งานภายนอก | C3: =COUNTIFS('Data Exchange'!$B$2:$B$51,$B3,'Data Exchange'!$H$2:$H$51,$C$2) -> 8 | D3: =COUNTIFS('Data Exchange'!$B$2:$B$51,$B3,'Data Exchange'!$H$2:$H$51,$D$2) -> 0 | E3: =COUNTIFS('Data Exchange'!$B$2:$B$51,$B3,'Data Exchange'!$H$2:$H$51,$E$2) -> 0 | F3: =COUNTIFS('Data Exchange'!$B$2:$B$51,$B3,'Data Exchange'!$H$2:$H$51,$F$2) -> 0 | G3: =COUNTIFS('Data Exchange'!$B$2:$B$51,$B3,'Data Exchange'!$H$2:$H$51,$G$2) -> 0 | H3: =COUNTIFS('Data Exchange'!$B$2:$B$51,$B3,'Data Exchange'!$H$2:$H$51,$H$2) -> 0 | I3: =SUM(C3:H3) -> 8
A4: 2 | B4: ผู้ใช้งานทั่วไป (ที่ยังไม่ได้รับสิทธิ์เข้าถึงข้อมูล Private) | C4: =COUNTIFS('Data Exchange'!$B$2:$B$51,$B4,'Data Exchange'!$H$2:$H$51,$C$2) -> 12 | D4: =COUNTIFS('Data Exchange'!$B$2:$B$51,$B4,'Data Exchange'!$H$2:$H$51,$D$2) -> 0 | E4: =COUNTIFS('Data Exchange'!$B$2:$B$51,$B4,'Data Exchange'!$H$2:$H$51,$E$2) -> 0 | F4: =COUNTIFS('Data Exchange'!$B$2:$B$51,$B4,'Data Exchange'!$H$2:$H$51,$F$2) -> 0 | G4: =COUNTIFS('Data Exchange'!$B$2:$B$51,$B4,'Data Exchange'!$H$2:$H$51,$G$2) -> 0 | H4: =COUNTIFS('Data Exchange'!$B$2:$B$51,$B4,'Data Exchange'!$H$2:$H$51,$H$2) -> 0 | I4: =SUM(C4:H4) -> 12
A5: 3 | B5: ผู้ใช้งานภายในที่มีสิทธิ์ใน Dataset | C5: =COUNTIFS('Data Exchange'!$B$2:$B$51,$B5,'Data Exchange'!$H$2:$H$51,$C$2) -> 4 | D5: =COUNTIFS('Data Exchange'!$B$2:$B$51,$B5,'Data Exchange'!$H$2:$H$51,$D$2) -> 0 | E5: =COUNTIFS('Data Exchange'!$B$2:$B$51,$B5,'Data Exchange'!$H$2:$H$51,$E$2) -> 0 | F5: =COUNTIFS('Data Exchange'!$B$2:$B$51,$B5,'Data Exchange'!$H$2:$H$51,$F$2) -> 0 | G5: =COUNTIFS('Data Exchange'!$B$2:$B$51,$B5,'Data Exchange'!$H$2:$H$51,$G$2) -> 0 | H5: =COUNTIFS('Data Exchange'!$B$2:$B$51,$B5,'Data Exchange'!$H$2:$H$51,$H$2) -> 0 | I5: =SUM(C5:H5) -> 4
A6: 4 | B6: ผู้ดูแลข้อมูลรายหน่วยงาน | C6: =COUNTIFS('Data Exchange'!$B$2:$B$51,$B6,'Data Exchange'!$H$2:$H$51,$C$2) -> 8 | D6: =COUNTIFS('Data Exchange'!$B$2:$B$51,$B6,'Data Exchange'!$H$2:$H$51,$D$2) -> 0 | E6: =COUNTIFS('Data Exchange'!$B$2:$B$51,$B6,'Data Exchange'!$H$2:$H$51,$E$2) -> 0 | F6: =COUNTIFS('Data Exchange'!$B$2:$B$51,$B6,'Data Exchange'!$H$2:$H$51,$F$2) -> 0 | G6: =COUNTIFS('Data Exchange'!$B$2:$B$51,$B6,'Data Exchange'!$H$2:$H$51,$G$2) -> 0 | H6: =COUNTIFS('Data Exchange'!$B$2:$B$51,$B6,'Data Exchange'!$H$2:$H$51,$H$2) -> 0 | I6: =SUM(C6:H6) -> 8
A7: 5 | B7: ผู้ดูแลระบบ | C7: =COUNTIFS('Data Exchange'!$B$2:$B$51,$B7,'Data Exchange'!$H$2:$H$51,$C$2) -> 13 | D7: =COUNTIFS('Data Exchange'!$B$2:$B$51,$B7,'Data Exchange'!$H$2:$H$51,$D$2) -> 0 | E7: =COUNTIFS('Data Exchange'!$B$2:$B$51,$B7,'Data Exchange'!$H$2:$H$51,$E$2) -> 0 | F7: =COUNTIFS('Data Exchange'!$B$2:$B$51,$B7,'Data Exchange'!$H$2:$H$51,$F$2) -> 0 | G7: =COUNTIFS('Data Exchange'!$B$2:$B$51,$B7,'Data Exchange'!$H$2:$H$51,$G$2) -> 0 | H7: =COUNTIFS('Data Exchange'!$B$2:$B$51,$B7,'Data Exchange'!$H$2:$H$51,$H$2) -> 0 | I7: =SUM(C7:H7) -> 13
A8: Total by Status | C8: =SUM(C3:C7) -> 45 | D8: =SUM(D3:D7) -> 0 | E8: =SUM(E3:E7) -> 0 | F8: =SUM(F3:F7) -> 0 | G8: =SUM(G3:G7) -> 0 | H8: =SUM(H3:H7) -> 0 | I8: =SUM(I3:I7) -> 45

Sheet Data Exchange
A1: Test Case No. | B1: Module | C1: Test Description | D1: Test Data | E1: Precondition | F1: Test Step | G1: Test Expected Result | H1: Test Result | I1: Planned UAT Date | J1: Actual UAT Date | K1: Test By | L1: Remark
A2: ผู้ใช้งานภายนอก (Scenario: ยังไม่สมัครหรือ Login เข้าระบบ เห็นเฉพาะ Landing Page และเริ่มต้นสมัครสมาชิกหรือ Login)
A3: EXT-001 | B3: ผู้ใช้งานภายนอก | C3: เข้าใช้งานหน้าระบบ (TOR : 5.7.8 (9)) | F3: 1. เปิด Chrome/Edge แบบ InPrivate และตรวจว่าไม่มี Session เดิม 2. เข้า URL : http://dexuat.duckdns.org:3003 ระบบจากแถบ Address 3. รอหน้า Landing Page โหลดจนเสร็จและเลื่อนจากส่วนบนถึง Footer 4. ตรวจเมนู ข้อความ สถิติ Features ขั้นตอนใช้งาน CTA และรูปภาพ | G3: หน้าโหลดสำเร็จ เมนู สถิติ Features ขั้นตอนใช้งาน CTA และ Footer แสดงครบ | H3: Not Executed
A4: EXT-002 | B4: ผู้ใช้งานภายนอก | C4: ทดสอบเมนูสาธารณะ(TOR : 5.7.8 (1),(2),(9) ) | F4: 1. เริ่มจากหน้า Landing Page โดยยังไม่ Login 2. คลิกเมนู หน้าแรก เกี่ยวกับเรา และติดต่อเรา ทีละรายการ 3. ตรวจ URL ชื่อหน้า Breadcrumb และเนื้อหาหลักหลังเปลี่ยนหน้า 4. ใช้ปุ่ม Back/Forward ของ Browser แล้วตรวจว่าหน้าไม่ผิดลำดับ 5. ตรวจว่าไม่มีหน้า 404 หน้าว่าง หรือข้อความ Error | G4: URL และเนื้อหาตรงเมนู ไม่มี 404 หรือหน้าว่าง | H4: Not Executed
A5: EXT-003 | B5: ผู้ใช้งานภายนอก | C5: สมัครสมาชิกครบขั้นตอน(TOR : 5.7.8 (1)-(4),(6),(7)) | F5: 1. เปิดหน้า Register จาก Landing/Login แล้วกด สมัครสมาชิก 2. กรอก Username และอีเมลไม่ซ้ำ พร้อม Password/Confirm Password ตรงกัน 3. กดถัดไป กรอกข้อมูลส่วนตัว หน่วยงาน/องค์กร(ไม่บังคับ) และช่องบังคับทุกขั้น 4. ตรวจทาน ยอมรับเงื่อนไข แล้วกดยืนยันสมัคร 5. ตรวจข้อความสำเร็จ สถานะรอยืนยันอีเมล และบันทึก Registration Log 6. ยืนยันอีเมลที่ถูกส่งไม่ mail ที่บันทึกไว้ | G5: ตรวจรูปแบบ/ความซ้ำ บันทึกสำเร็จ ส่งยืนยันอีเมล และเข้าสถานะรออนุมัติ | H5: Not Executed
A6: EXT-004 | B6: ผู้ใช้งานภายนอก | C6: เข้าสู่ระบบสำเร็จ (TOR : 5.7.8 (8)) | F6: 1. เปิดหน้า Login และกรอกข้อมูลถูกต้อง 2. เลือก/ไม่เลือก Remember me ตามรอบทดสอบแล้วกดเข้าสู่ระบบ 3. รอ Redirect และตรวจชื่อผู้ใช้ บทบาท เมนู และหน้าเริ่มต้น 4. Refresh หน้าเพื่อยืนยัน Session และบันทึกภาพหลัง Login | G6: เข้าสู่หน้าที่กำหนดตามบทบาท สร้าง Session และแสดงชื่อผู้ใช้ถูกต้อง | H6: Not Executed
A7: EXT-005 | B7: ผู้ใช้งานภายนอก | C7: ออกจากระบบ (TOR : 5.7.8 (8)) | F7: 1. Login ด้วยบัญชี Active ให้สำเร็จ 2. กดเมนูผู้ใช้และเลือก ออกจากระบบ 3. ตรวจว่า Redirect ไป Landing/Login และชื่อผู้ใช้หายไป 4. กด Back และเปิด URL ภายในจาก Bookmark 5. ตรวจว่าระบบขอ Login ใหม่และ Session เดิมใช้ไม่ได้ | G7: ล้าง Session และถูกส่งกลับหน้าเข้าสู่ระบบทุกกรณี | H7: Not Executed
A8: EXT-006 | B8: ผู้ใช้งานภายนอก | C8: เข้าสู่ระบบผิด (TOR : 5.7.8 (8)) | F8: 1. เปิดหน้า Login ในหน้าต่างใหม่ที่ไม่มี Session 2. กรอก Username ถูกต้องและ Password ผิด 3. กดเข้าสู่ระบบหนึ่งครั้งและบันทึกข้อความแจ้งเตือน/จำนวนครั้งคงเหลือ 4. ตรวจว่า URL ยังเป็นหน้า Login และเมนูภายในไม่ปรากฏ 5. ตรวจ Log การเข้าสู่ระบบล้มเหลวด้วยบัญชี | G8: ไม่สร้าง Session ไม่เปิดเผยว่าฟิลด์ใดถูก และแสดงจำนวนครั้งคงเหลือเหมาะสม | H8: Not Executed
A9: EXT-007 | B9: ผู้ใช้งานภายนอก | C9: ลืมรหัสผ่าน(TOR : 5.7.8 (8)) | F9: 1. เปิดหน้า Login และคลิก Forgot password 2. กรอก Username ที่มีอีเมลลงทะเบียนแล้วและกดส่งคำขอ 3. ตรวจข้อความยืนยันและกล่องอีเมลของบัญชีทดสอบ 4. ใช้ลิงก์/รหัสที่ได้รับตั้งรหัสผ่านใหม่ตามนโยบาย 5. ทดสอบลิงก์เดิมซ้ำและ Login ด้วยรหัสใหม่เพื่อยืนยันการหมดอายุ/ใช้ซ้ำไม่ได้ | G9: ส่งคำขอสำเร็จ ลิงก์/รหัสหมดอายุ ใช้ซ้ำไม่ได้ และไม่เปิดเผยการมีอยู่ของบัญชี | H9: Not Executed
A10: EXT-008 | B10: ผู้ใช้งานภายนอก | C10: ล็อกบัญชีเมื่อผิดซ้ำ (TOR : 5.7.8 (8)) | F10: 1. เตรียมบัญชีทดสอบสำหรับล็อกโดยเฉพาะ 2. กรอก Password ผิดซ้ำตามจำนวนครั้งสูงสุดที่กำหนด 3. บันทึกข้อความทุกครั้งและเวลาที่บัญชีถูกล็อก 4. กรอก Password ถูกต้องทันทีหลังถูกล็อก 5. ตรวจว่ายังเข้าไม่ได้ มีข้อความ/วิธีปลดล็อก และมี Audit Log | G10: บัญชีถูกล็อกชั่วคราว มี Audit Log และแจ้งวิธีปลดล็อก | H10: Not Executed
A11: ผู้ใช้งานทั่วไป (ที่ยังไม่ได้รับสิทธิ์เข้าถึงข้อมูล Private) (Scenario: สมัครเข้าสู่ระบบแล้ว เห็นข้อมูล Public แต่ข้อมูล Private จะเห็นเฉพาะ Metadata และต้องร้องขอสิทธิ์ก่อน)
A12: GEN-001 | B12: ผู้ใช้งานทั่วไป (ที่ยังไม่ได้รับสิทธิ์เข้าถึงข้อมูล Private) | C12: Login สำเร็จ (TOR : 5.7.8 (8)) | F12: 1. เข้า URL ระบบ Data Exchange 2. กรอก Username : ตามที่กำหนด 3. กรอก Password : ตามที่กำหนด 4. กดปุ่ม Login (เข้าสู่ระบบ) 5. รอ redirect ไปหน้าหลัก | G12: เข้าสู่หน้าที่กำหนดตามบทบาท สร้าง Session และแสดงชื่อผู้ใช้ถูกต้อง | H12: Not Executed
A13: GEN-002 | B13: ผู้ใช้งานทั่วไป (ที่ยังไม่ได้รับสิทธิ์เข้าถึงข้อมูล Private) | C13: ค้นหาด้วยคำสำคัญ (TOR : 5.7.8 (9)) | F13: 1. Login ด้วยผู้ใช้ทั่วไปแล้วเปิดเมนู บัญชีข้อมูล 2. กรอกคำค้นจากชื่อ Dataset ภาษาไทยและกดค้นหา 3. ล้างค่าและค้นด้วยคำภาษาอังกฤษ/คำใน Tag 4. เลือกคำแนะนำ Auto Complete ถ้ามี 5. ตรวจผลลัพธ์ จำนวนรายการ คำค้น และความเกี่ยวข้องของข้อมูล | G13: รายการตรงเงื่อนไข จำนวนผลลัพธ์และคำค้นแสดงถูกต้อง | H13: Not Executed
A14: GEN-003 | B14: ผู้ใช้งานทั่วไป (ที่ยังไม่ได้รับสิทธิ์เข้าถึงข้อมูล Private) | C14: ตัวกรองและล้างค่า (TOR : 5.7.8 (9)) | F14: 1. เปิด Catalog ด้วยค่าตั้งต้นและบันทึกจำนวนรวม 2. เลือกหมวดหมู่หนึ่ง ระดับการเข้าถึง และรูปแบบไฟล์ 3. ตรวจรายการหลังเลือกแต่ละ Filter และตัวเลข Facet 4. เลือกหลายค่าตามที่ระบบรองรับ แล้ว Refresh หน้า 5. กดล้าง Filter และยืนยันค่ากับจำนวนรวมกลับสู่ค่าเริ่มต้น | G14: ผลลัพธ์เป็น AND/OR ตามข้อกำหนด ตัวเลข facet ถูกต้อง และกลับค่าเริ่มต้นเมื่อล้าง | H14: Not Executed
A15: GEN-004 | B15: ผู้ใช้งานทั่วไป (ที่ยังไม่ได้รับสิทธิ์เข้าถึงข้อมูล Private) | C15: เรียงลำดับและแบ่งหน้า(TOR : 5.7.8 (9)) | F15: 1. ค้นหา/กรองให้ได้ผลลัพธ์มากกว่าหนึ่งหน้า 2. เลือกเรียงตาม เกี่ยวข้องมากที่สุด แล้วบันทึกลำดับ 3 รายการแรก 3. เปลี่ยนเป็น ใหม่ล่าสุด และยอดนิยม ทีละค่า 4. เปลี่ยนหน้าไปหน้า 2 แล้วกลับหน้า 1 5. ตรวจไม่มีรายการซ้ำ/ตกหล่น และ Filter/Sort ยังคงเดิม | G15: ลำดับถูกต้อง ไม่ซ้ำ/ตกหล่น และคง filter ข้ามหน้า | H15: Not Executed
A16: GEN-005 | B16: ผู้ใช้งานทั่วไป (ที่ยังไม่ได้รับสิทธิ์เข้าถึงข้อมูล Private) | C16: รายละเอียดชุดข้อมูล (TOR : 5.7.2; 5.7.8 (9)) | F16: 1. จาก Catalog คลิก Dataset ที่กำหนดไว้ในข้อมูลทดสอบ 2. ตรวจชื่อ Dataset ID เจ้าของ คำอธิบาย หมวดหมู่ Sensitivity และรูปแบบไฟล์ 3. ตรวจจำนวนระเบียน วันที่สร้าง/ปรับปรุง Tags และ Metadata อื่น 4. ตรวจปุ่ม Download, Request Access หรือ API ให้ตรงสิทธิ์ | G16: ชื่อ เจ้าของ คำอธิบาย Sensitivity รูปแบบ จำนวนระเบียน วันที่ และ Metadata แสดงถูกต้องไม่มีข้อมูลผิดรูปแบบ | H16: Not Executed
A17: GEN-006 | B17: ผู้ใช้งานทั่วไป (ที่ยังไม่ได้รับสิทธิ์เข้าถึงข้อมูล Private) | C17: รายการโปรด(TOR : 5.7.8 (9)) | F17: 1. Login ด้วยผู้ใช้ทั่วไปและเปิด Dataset ที่ยังไม่เป็นรายการโปรด 2. คลิกไอคอนเพิ่มรายการโปรดและตรวจสถานะเปลี่ยน 3. เปิดเมนูรายการโปรดและยืนยันว่าพบ Dataset 4. ลบออกจากรายการโปรดและยืนยันว่าหายทั้งสองหน้า | G17: สถานะโปรดเปลี่ยนทันทีและคงอยู่เฉพาะผู้ใช้ | H17: Not Executed
A18: GEN-007 | B18: ผู้ใช้งานทั่วไป (ที่ยังไม่ได้รับสิทธิ์เข้าถึงข้อมูล Private) | C18: ดาวน์โหลด Public (TOR : 5.7.8 (9) ) | F18: 1. เลือก Dataset แบบ Public ที่มีไฟล์ CSV/XLS 2. กด Download/Export และเลือกรูปแบบแรก 3. เปิดไฟล์ ตรวจชื่อไฟล์ Header Encoding จำนวนแถวตัวอย่าง และข้อมูล | G18: ไฟล์ดาวน์โหลดได้ ชื่อ/ชนิด/encoding/ข้อมูลถูกต้อง | H18: Not Executed
A19: GEN-008 | B19: ผู้ใช้งานทั่วไป (ที่ยังไม่ได้รับสิทธิ์เข้าถึงข้อมูล Private) | C19: ขอสิทธิ์ Restricted/PII (TOR : 5.7.5 (3)-(8); 5.7.8 (9)) | F19: 1. Login ด้วยผู้ใช้ทั่วไปที่ยังไม่มีสิทธิ์ Dataset Private 2. เปิดรายละเอียด Dataset และยืนยันว่าเห็นเฉพาะ Metadata 3. กด Request Access เลือก Dataset/Field ระบุวัตถุประสงค์ 4. ตรวจทานแล้วกดส่งเพียงครั้งเดียว 5. ตรวจเลขคำขอ สถานะ Pending การแจ้งเตือน และไม่สามารถดาวน์โหลดก่อนอนุมัติ | G19: เปิดหน้าหรือเมนูที่ระบุได้สำเร็จ และระบบแสดงเฉพาะเมนูที่บทบาทนี้มีสิทธิ์ ไม่สามารถดาวน์โหลดไฟล์หรือดูข้อมูลได้ก่อนอนุมัติ ขึ้นสถานะรออนุมัติ | H19: Not Executed
A20: GEN-009 | B20: ผู้ใช้งานทั่วไป (ที่ยังไม่ได้รับสิทธิ์เข้าถึงข้อมูล Private) | C20: ตรวจข้อมูล Private ก่อนอนุมัติ (TOR : 5.7.5 (8); 5.7.8 (4),(9)) | F20: 1. Login ด้วยผู้ใช้ทั่วไปที่ไม่มีสิทธิ์ Dataset Private 2. ค้นหา Dataset Private จาก Catalog และเปิดรายละเอียด 3. ตรวจ Metadata ที่อนุญาตให้แสดงและลองคลิก Download/API หามี Function ขึ้นมาให้กด | G20: เห็นเฉพาะ Metadata ไม่เห็นเนื้อหาหรือดาวน์โหลด และมีปุ่มร้องขอสิทธิ์ | H20: Not Executed
A21: GEN-010 | B21: ผู้ใช้งานทั่วไป (ที่ยังไม่ได้รับสิทธิ์เข้าถึงข้อมูล Private) | C21: แก้ไขโปรไฟล์(TOR : 5.7.8 (8),(9)) | F21: 1. Login ด้วยผู้ใช้ทั่วไปและเปิด Profile > Personal Info 2. บันทึกค่าเดิม แล้วแก้ First Name, Last Name และ Usage Objectiveแล้วกด Save Changes 3. Refresh/Logout-Login และตรวจข้อมูล Header/Profile | G21: Save ตรวจรูปแบบและบันทึก Header อัปเดตสอดคล้อง | H21: Not Executed
A22: GEN-011 | B22: ผู้ใช้งานทั่วไป (ที่ยังไม่ได้รับสิทธิ์เข้าถึงข้อมูล Private) | C22: เปลี่ยนรหัสผ่านจากหน้าโปร์ไฟล์(TOR : 5.7.8 (8)) | F22: 1. เปิด Profile > Security ด้วยบัญชีทดสอบ 2. กรอกรหัสผ่านเดิม รหัสใหม่ที่ผ่าน Policy และ Confirm ให้ตรง 3. กดบันทึกและตรวจข้อความสำเร็จ 4. ทดลองใช้ Session เก่าหรือ Browser อีกหน้าต่าง 5. Logout แล้ว Login ด้วยรหัสเดิมและรหัสใหม่เพื่อยืนยันการเปลี่ยน | G22: ตรวจรหัสเดิม/ความแข็งแรง เปลี่ยนสำเร็จ ยกเลิก Session เก่า และไม่เก็บรหัสผ่านแบบอ่านได้ | H22: Not Executed
A23: GEN-012 | B23: ผู้ใช้งานทั่วไป (ที่ยังไม่ได้รับสิทธิ์เข้าถึงข้อมูล Private) | C23: ตรวจข้อมูล Private ก่อนอนุมัติ (TOR : 5.7.5 (8); 5.7.8 (4),(9)) | F23: 1. Login ด้วยผู้ใช้ทั่วไปที่ไม่มีสิทธิ์ Dataset Private 2. ค้นหา Dataset Private จาก Catalog และเปิดรายละเอียด 3. ตรวจ Metadata ที่อนุญาตให้แสดงและลองคลิก Download/API 4. เปิด Developer Tools ตรวจ Response เพื่อยืนยันว่าไม่มีเนื้อหาถูกส่ง | G23: เห็นเฉพาะ Metadata ไม่เห็นเนื้อหาหรือดาวน์โหลด และมีปุ่มร้องขอสิทธิ์ | H23: Not Executed
A24: ผู้ใช้งานภายในที่มีสิทธิ์ใน Dataset (Scenario : Login และได้รับสิทธิ์แล้ว สามารถเข้าถึงข้อมูลตาม Dataset และ Field ที่ได้รับอนุมัติเท่านั้น)
A25: INT-001 | B25: ผู้ใช้งานภายในที่มีสิทธิ์ใน Dataset | C25: เข้าถึง Dataset หลังได้รับสิทธิ์ (TOR : 5.7.5 (3)-(5),(8); 5.7.8 (9)) | F25: 1. ให้ผู้ดูแลอนุมัติสิทธิ์ Dataset Private แก่ผู้ใช้ภายใน 2. Logout/Login ใหม่ด้วยผู้ใช้ภายใน 3. เปิด Dataset จาก Catalog/ลิงก์ตรงและดูรายละเอียด 4. ตรวจสถานะสิทธิ์ ข้อมูลที่เห็น | G25: เข้าถึง Dataset ได้ตามช่วงเวลาและสิทธิ์ที่อนุมัติ | H25: Not Executed
A26: INT-002 | B26: ผู้ใช้งานภายในที่มีสิทธิ์ใน Dataset | C26: ดาวน์โหลด ข้อมูล Private ที่ได้รับสิทธิ์ (TOR : 5.7.8 (9)) | F26: 1. Login ด้วยผู้ใช้ภายในที่ได้รับสิทธิ์ Dataset Private แล้ว 2. เปิด Dataset และเลือก Export รูปแบบที่ได้รับอนุมัติ 3. ดาวน์โหลดและเปิดไฟล์ ตรวจชื่อ Dataset, Field และจำนวนแถวตัวอย่าง | G26: ดาวน์โหลดได้เฉพาะรูปแบบและข้อมูลที่อนุมัติ พร้อมบันทึก Log | H26: Not Executed
A27: INT-003 | B27: ผู้ใช้งานภายในที่มีสิทธิ์ใน Dataset | C27: เข้าถึงพจนาณุกรมข้อมูลได้เห็น , Field และจำนวนแถวตัวอย่าง | F27: 1. เปิด Dataset และเลือก พจนาณุกรม 2. ตรวจชื่อ Dataset, Field และจำนวนแถวตัวอย่าง | G27: แสดง Dataset, Field และจำนวนแถวตัวอย่างตามสิทธิ์ | H27: Not Executed
A28: INT-004 | B28: ผู้ใช้งานภายในที่มีสิทธิ์ใน Dataset | C28: เข้าถึง Dashboard ได้ตามสิทธิ์ | F28: 1. เปิด Dataset และเลือก Dashboard 2. สามารถเข้าถึง Dashboard และเข้าชมได้ตามสิทธิ์ | G28: แสดง Dashboard และเข้าชมได้ตามสิทธิ์ | H28: Not Executed
A29: ผู้ดูแลข้อมูลรายหน่วยงาน (Scenario: สร้าง Dataset,จัดการข้อมูลของหน่วยงานตนเองและอนุมัติสิทธิ์ให้ผู้ร้องขอเข้าถึงข้อมูลของหน่วยงาน)
A30: ORG-001 | B30: ผู้ดูแลข้อมูลรายหน่วยงาน | C30: Login สำเร็จ (TOR : 5.7.8 (8)) | F30: 1. เข้า URL ระบบ Data Exchange 2. กรอก Username : ตามที่กำหนด 3. กรอก Password : ตามที่กำหนด 4. กดปุ่ม Login (เข้าสู่ระบบ) 5. รอ redirect ไปหน้าหลัก | G30: เข้าสู่หน้าที่กำหนดตามบทบาท สร้าง Session และแสดงชื่อผู้ใช้ถูกต้อง | H30: Not Executed
A31: ORG-002 | B31: ผู้ดูแลข้อมูลรายหน่วยงาน | C31: สร้างชุดข้อมูลข้อมูลครบ(TOR : 5.7.2; 5.7.7 (14)-(16)) | F31: 1. Login ด้วยผู้ดูแลข้อมูลรายหน่วยงานและเปิด Dataset Management 2. กดเพิ่ม/สร้างชุดข้อมูลใหม่และเลือกประเภทข้อมูล 3. กรอก Core Info, Governance, Technical และ Visualization ด้วยรหัส UAT-DS-002 4. เลือกหน่วยงานตนเองและสถานะ active ก่อน 5. กดบันทึก ตรวจข้อความสำเร็จ และค้นหา Dataset ที่สร้าง | G31: สร้าง Dataset ID ไม่ซ้ำ ค่า Metadata ครบ และ Active/Inactive มีผลตามกำหนด | H31: Not Executed
A32: ORG-003 | B32: ผู้ดูแลข้อมูลรายหน่วยงาน | C32: เพิ่มไฟล์ชุดข้อมูล (TOR : 5.7.6 (1),(2); 5.7.7 (1)) | F32: 1. เปิด Dataset ที่สร้างและเลือกเมนูเพิ่มไฟล์ 2. อัปโหลดไฟล์ CSV/Excel ที่ถูกต้องและรอ Validation | G32: ไฟล์ถูกต้องผ่าน Validation; ไฟล์ผิดถูกปฏิเสธโดยไม่ค้างไฟล์ชั่วคราว | H32: Not Executed
A33: ORG-004 | B33: ผู้ดูแลข้อมูลรายหน่วยงาน | C33: เพิ่มลิงก์และสร้าง Dashbaord (TOR : 5.7.6 (1),(2); 5.7.7 (1)) | F33: 1. เปิด Dataset Management ค้นชุดข้อมูล UAT-DS-002 กดแก้ไข 2. เลือกเพิ่มลิงก์ กรอก URL Resource ที่เข้าถึงได้และบันทึก 3. บันทึกแล้วตรวจ Resource/Dashboard Management ว่าผูกกับ Dataset ถูกต้อง | G33: ตรวจ URL/การเชื่อมต่อ สร้าง ถูกชุดข้อมูลสามารถเข้าใช้งานได้ | H33: Not Executed
A34: ORG-005 | B34: ผู้ดูแลข้อมูลรายหน่วยงาน | C34: แก้ไข/ปิดใช้งาน(TOR : 5.7.2; 5.7.5 (1)) | F34: 1. เปิด Dataset ที่มีอยู่ใน Dataset Management 2. กด Edit เปลี่ยนคำอธิบาย Tags และวันที่ปรับปรุง แล้วบันทึก 3. เปิดหน้ารายละเอียดเพื่อยืนยันค่าใหม่ 4. กลับมาเปลี่ยนสถานะ Active เป็น Inactive 5. เปิด Catalog ด้วย User อื่นและตรวจว่าไม่พบ | G34: ประวัติแก้ไขครบ ค่าใหม่แสดงถูก และ Inactive ไม่ปรากฏหน้าสาธารณะ | H34: Not Executed
A35: ORG-006 | B35: ผู้ดูแลข้อมูลรายหน่วยงาน | C35: รายการ Dataset Management (TOR : 5.7.2; 5.7.7 (12),(14)) | F35: 1. เปิด Dataset Management และบันทึก Total/Active/Inactive 2. กรองตามหมวดหมู่และสถานะทีละค่า 3. ค้นหา Dataset ID/Name ที่กำหนด 4. เปิด Action View/Edit ของรายการที่มีสิทธิ์ 5. เปรียบเทียบจำนวนสรุปกับรายการและตรวจว่า Action ตรงบทบาท | G35: ยอด Total/Active/Inactive ตรงรายการ ตัวกรองและ Action ทำงานถูกสิทธิ์ | H35: Not Executed
A36: ORG-007 | B36: ผู้ดูแลข้อมูลรายหน่วยงาน | C36: โหลดคำขอสิทธิ์ข้อมูล (TOR : 5.7.8 (9)) | F36: 1. เตรียมคำขอเข้าถึง Dataset ของหน่วยงานตนเองหนึ่งรายการ 2. Login ด้วยผู้ดูแลข้อมูลรายหน่วยงานและเปิดหน้าคำขอสิทธิ์ 3. กด Refresh/เลือกแท็บคำขอข้อมูลและค้นหาเลขคำขอ 4. ยืนยันว่าข้อมูลโหลดได้ครบโดยไม่ขึ้น Error และยังไม่อนุมัติในเคสนี้ | G36: โหลดรายการได้โดยไม่ขึ้นข้อผิดพลาด แยกคำขอสมาชิก/ข้อมูลถูกต้อง | H36: Not Executed
A37: ORG-008 | B37: ผู้ดูแลข้อมูลรายหน่วยงาน | C37: อนุมัติสิทธิ์เฉพาะข้อมูลของหน่วย งาน (TOR : 5.7.8 (9)) | F37: 1. เตรียมคำขอสิทธิ์ Dataset ของหน่วยงาน 2. Login ด้วยผู้ดูแลข้อมูลหน่วยงานและเปิดหน้า คำขอ 3. อนุมัติคำขอของหน่วยงาน 4. ค้นหา/เปิดคำขอของหน่วยงาน B และทดลองอนุมัติ 5. ตรวจว่าอนุมัติ A สำเร็จ | G37: อนุมัติได้เฉพาะคำขอของหน่วยงานตน คำขออื่นไม่แสดงหรือถูกปฏิเสธ | H37: Not Executed
A38: ผู้ดูแลระบบ (Scenario: จัดการผู้ใช้ การสมัคร สิทธิ์ กลุ่ม Dataset/API การอนุมัติคำขอ และติดตามการใช้งานทั้งระบบ)
A39: ADM-001 | B39: ผู้ดูแลระบบ | C39: Login สำเร็จ (TOR : 5.7.8 (8)) | F39: 1. เข้า URL ระบบ Data Exchange 2. กรอก Username : ตามที่กำหนด 3. กรอก Password : ตามที่กำหนด 4. กดปุ่ม Login (เข้าสู่ระบบ) 5. รอ redirect ไปหน้าหลัก | G39: เข้าสู่หน้าที่กำหนดตามบทบาท สร้าง Session และแสดงชื่อผู้ใช้ถูกต้อง | H39: Not Executed
A40: ADM-002 | B40: ผู้ดูแลระบบ | C40: รายการ API General - เพิ่มและแก้ไข API (TOR : 5.7.5 (1)-(11), 5.7.7 (16) | F40: ไปที่เมนู API Management > API General ตรวจสอบรายการ API ทั้งหมดที่แสดงในระบบ เลือก API ที่ต้องการกำหนดสิทธิ์ให้ผู้ใช้งาน คลิกปุ่ม ADD USER ค้นหาและเลือกผู้ใช้งานที่ต้องการให้สิทธิ์ กำหนดสิทธิ์การเข้าถึง API ให้แก่ผู้ใช้งาน ตั้งค่าวันและเวลาหมดอายุของสิทธิ์การเข้าถึง API ทดสอบเปิดและปิดสิทธิ์การเข้าถึง API ของผู้ใช้งานชั่วคราว ถอนสิทธิ์หรือลบสิทธิ์การเข้าถึง API ของผู้ใช้งานอย่างถาวร | G40: ผู้ดูแลระบบสามารถตรวจสอบรายการ API เพิ่มผู้ใช้งาน และกำหนดสิทธิ์การเข้าถึง API ได้สำเร็จ รวมถึงสามารถตั้งค่าวันหมดอายุ เปิด–ปิดสิทธิ์ชั่วคราว และถอนสิทธิ์อย่างถาวรได้ตามที่กำหนด | H40: Not Executed
...

Sheet สูตร
A1: Status | B1: คำอธิบาย
A2: Not Executed | B2: ยังไม่เริ่มทดสอบ
A3: In Progress | B3: กำลังดำเนินการทดสอบ
A4: Passed | B4: ผลการทดสอบผ่าน
A5: Skipped | B5: ข้ามการทดสอบ
A6: Failed | B6: ผลการทดสอบไม่ผ่าน
A7: Blocked | B7: ไม่สามารถทดสอบต่อได้
